Workbook

Sheet Raw_Data
A1: Order_ID | B1: Order_Time | C1: Order_Type | D1: Prep_Time | E1: Ready_Time | F1: Rider_Assigned_Time | G1: Pickup_Time | H1: Delivery_Time | I1: Distance_km | J1: Rider_ID | K1: Order_Value | L1: Delivery_Cost | M1: Status | N1: Rider_Availability | O1: Traffic_Level | P1: Delivery_Failure | Q1: Delay_Reason
A2: O1 | B2: 12:17 | C2: Normal | D2: 11 | E2: 12:28 | F2: 12:31 | G2: 0.52361111 | H2: 13:05 | I2: 4.47 | J2: R7 | K2: 247 | L2: 94 | M2: Delivered | N2: 14 | O2: Medium | P2: No | Q2: =IF(M2="Failed", IF(O2="High","Traffic", IF(N2<10,"No Rider","Restaurant Delay")), IF(((H2-B2)*1440 - (D2 + I2*5))<=7,"None", IF(O2="High","Traffic", IF(N2<10,"No Rider", IF(C2="Bulk","Restaurant Delay", IF(I2>=6,"Distance","None")))))) -> None
A3: O2 | B3: 11:36 | C3: Normal | D3: 16 | E3: 11:52 | F3: 11:52 | G3: 0.49861111 | H3: 12:39 | I3: 6.34 | J3: R8 | K3: 218 | L3: 117 | M3: Delivered | N3: 15 | O3: Medium | P3: No | Q3: =IF(M3="Failed", IF(O3="High","Traffic", IF(N3<10,"No Rider","Restaurant Delay")), IF(((H3-B3)*1440 - (D3 + I3*5))<=7,"None", IF(O3="High","Traffic", IF(N3<10,"No Rider", IF(C3="Bulk","Restaurant Delay", IF(I3>=6,"Distance","None")))))) -> Distance
A4: O3 | B4: 11:44 | C4: Normal | D4: 10 | E4: 11:54 | F4: 11:54 | G4: 0.49722222 | H4: 12:33 | I4: 5.55 | J4: R7 | K4: 247 | L4: 105 | M4: Delivered | N4: 12 | O4: Medium | P4: No | Q4: =IF(M4="Failed", IF(O4="High","Traffic", IF(N4<10,"No Rider","Restaurant Delay")), IF(((H4-B4)*1440 - (D4 + I4*5))<=7,"None", IF(O4="High","Traffic", IF(N4<10,"No Rider", IF(C4="Bulk","Restaurant Delay", IF(I4>=6,"Distance","None")))))) -> None
A5: O4 | B5: 17:12 | C5: Normal | D5: 18 | E5: 17:30 | F5: 17:31 | G5: 0.73055556 | H5: 18:23 | I5: 7.57 | J5: R8 | K5: 323 | L5: 128 | M5: Delivered | N5: 13 | O5: Medium | P5: No | Q5: =IF(M5="Failed", IF(O5="High","Traffic", IF(N5<10,"No Rider","Restaurant Delay")), IF(((H5-B5)*1440 - (D5 + I5*5))<=7,"None", IF(O5="High","Traffic", IF(N5<10,"No Rider", IF(C5="Bulk","Restaurant Delay", IF(I5>=6,"Distance","None")))))) -> Distance
A6: O5 | B6: 17:50 | C6: Normal | D6: 10 | E6: 18:00 | F6: 18:00 | G6: 0.75069444 | H6: 18:53 | I6: 7.46 | J6: R10 | K6: 335 | L6: 128 | M6: Delivered | N6: 15 | O6: Medium | P6: No | Q6: =IF(M6="Failed", IF(O6="High","Traffic", IF(N6<10,"No Rider","Restaurant Delay")), IF(((H6-B6)*1440 - (D6 + I6*5))<=7,"None", IF(O6="High","Traffic", IF(N6<10,"No Rider", IF(C6="Bulk","Restaurant Delay", IF(I6>=6,"Distance","None")))))) -> Distance
A7: O6 | B7: 12:03 | C7: Normal | D7: 18 | E7: 12:21 | F7: 12:22 | G7: 0.51805556 | H7: 13:12 | I7: 6.81 | J7: R16 | K7: 300 | L7: 122 | M7: Delivered | N7: 15 | O7: Medium | P7: No | Q7: =IF(M7="Failed", IF(O7="High","Traffic", IF(N7<10,"No Rider","Restaurant Delay")), IF(((H7-B7)*1440 - (D7 + I7*5))<=7,"None", IF(O7="High","Traffic", IF(N7<10,"No Rider", IF(C7="Bulk","Restaurant Delay", IF(I7>=6,"Distance","None")))))) -> Distance
A8: O7 | B8: 18:37 | C8: Normal | D8: 10 | E8: 18:47 | F8: 18:50 | G8: 0.78888889 | H8: 19:34 | I8: 6.21 | J8: R12 | K8: 194 | L8: 113 | M8: Delivered | N8: 15 | O8: Medium | P8: No | Q8: =IF(M8="Failed", IF(O8="High","Traffic", IF(N8<10,"No Rider","Restaurant Delay")), IF(((H8-B8)*1440 - (D8 + I8*5))<=7,"None", IF(O8="High","Traffic", IF(N8<10,"No Rider", IF(C8="Bulk","Restaurant Delay", IF(I8>=6,"Distance","None")))))) -> Distance
A9: O8 | B9: 19:21 | C9: Normal | D9: 20 | E9: 19:41 | F9: 19:41 | G9: 0.82708333 | H9: 20:19 | I9: 4.07 | J9: R13 | K9: 283 | L9: 96 | M9: Delivered | N9: 10 | O9: High | P9: No | Q9: =IF(M9="Failed", IF(O9="High","Traffic", IF(N9<10,"No Rider","Restaurant Delay")), IF(((H9-B9)*1440 - (D9 + I9*5))<=7,"None", IF(O9="High","Traffic", IF(N9<10,"No Rider", IF(C9="Bulk","Restaurant Delay", IF(I9>=6,"Distance","None")))))) -> Traffic
A10: O9 | B10: 16:19 | C10: Normal | D10: 10 | E10: 16:29 | F10: 16:32 | G10: 0.69236111 | H10: 16:54 | I10: 3.16 | J10: R17 | K10: 193 | L10: 76 | M10: Delivered | N10: 18 | O10: Low | P10: No | Q10: =IF(M10="Failed", IF(O10="High","Traffic", IF(N10<10,"No Rider","Restaurant Delay")), IF(((H10-B10)*1440 - (D10 + I10*5))<=7,"None", IF(O10="High","Traffic", IF(N10<10,"No Rider", IF(C10="Bulk","Restaurant Delay", IF(I10>=6,"Distance","None")))))) -> None
A11: O10 | B11: 13:52 | C11: Normal | D11: 13 | E11: 14:05 | F11: 14:07 | G11: 0.58888889 | H11: 14:36 | I11: 2.63 | J11: R12 | K11: 297 | L11: 80 | M11: Delivered | N11: 16 | O11: Medium | P11: No | Q11: =IF(M11="Failed", IF(O11="High","Traffic", IF(N11<10,"No Rider","Restaurant Delay")), IF(((H11-B11)*1440 - (D11 + I11*5))<=7,"None", IF(O11="High","Traffic", IF(N11<10,"No Rider", IF(C11="Bulk","Restaurant Delay", IF(I11>=6,"Distance","None")))))) -> None
A12: O11 | B12: 17:50 | C12: Normal | D12: 20 | E12: 18:10 | F12: 18:10 | G12: 0.76111111 | H12: 19:04 | I12: 7.7 | J12: R17 | K12: 369 | L12: 131 | M12: Delivered | N12: 16 | O12: Medium | P12: No | Q12: =IF(M12="Failed", IF(O12="High","Traffic", IF(N12<10,"No Rider","Restaurant Delay")), IF(((H12-B12)*1440 - (D12 + I12*5))<=7,"None", IF(O12="High","Traffic", IF(N12<10,"No Rider", IF(C12="Bulk","Restaurant Delay", IF(I12>=6,"Distance","None")))))) -> Distance
A13: O12 | B13: 12:12 | C13: Normal | D13: 18 | E13: 12:30 | F13: 12:33 | G13: 0.52361111 | H13: 13:26 | I13: 7.65 | J13: R18 | K13: 295 | L13: 129 | M13: Delivered | N13: 13 | O13: Medium | P13: No | Q13: =IF(M13="Failed", IF(O13="High","Traffic", IF(N13<10,"No Rider","Restaurant Delay")), IF(((H13-B13)*1440 - (D13 + I13*5))<=7,"None", IF(O13="High","Traffic", IF(N13<10,"No Rider", IF(C13="Bulk","Restaurant Delay", IF(I13>=6,"Distance","None")))))) -> Distance
... A251: O250 | B251: 17:44 | C251: Normal | D251: 15 | E251: 17:59 | F251: 18:02 | G251: 0.75347222 | H251: 18:53 | I251: 7.56 | J251: R15 | K251: 333 | L251: 127 | M251: Failed | N251: 16 | O251: Medium | P251: Yes | Q251: =IF(M251="Failed", IF(O251="High","Traffic", IF(N251<10,"No Rider","Restaurant Delay")), IF(((H251-B251)*1440 - (D251 + I251*5))<=7,"None", IF(O251="High","Traffic", IF(N251<10,"No Rider", IF(C251="Bulk","Restaurant Delay", IF(I251>=6,"Distance","None")))))) -> Restaurant Delay

Sheet Processed_Data
A1: Order_ID | B1: Order_Time | C1: Order_Type | D1: Prep_Time | E1: Ready_Time | F1: Rider_Assigned_Time | G1: Pickup_Time | H1: Delivery_Time | I1: Distance_km | J1: Rider_ID | K1: Order_Value | L1: Delivery_Cost | M1: Status | N1: Rider_Availability | O1: Traffic_Level | P1: Delivery_Failure | Q1: Delay_Reason | R1: Total_Delivery_Time | S1: Prep_Wait_Time | T1: Pickup_Lag | U1: Transit_Time | V1: Hour_of_Day | W1: Time_Slot | X1: Is_Peak_Hour | Y1: Delivery_Speed_kmpm | Z1: Cost_Per_km | AA1: Delivery_Cost_Ratio | AB1: Is_Late (Define Late as >45min) | AC1: Delay_Category | AD1: Distance_Bucket
A2: O1 | B2: 12:17 | C2: Normal | D2: 11 | E2: 12:28 | F2: 12:31 | G2: 0.52361111 | H2: 13:05 | I2: 4.47 | J2: R7 | K2: 247 | L2: 94 | M2: Delivered | N2: 14 | O2: Medium | P2: No | Q2: =IF(M2="Failed", IF(O2="High","Traffic", IF(N2<10,"No Rider","Restaurant Delay")), IF(((H2-B2)*1440 - (D2 + I2*5))<=7,"None", IF(O2="High","Traffic", IF(N2<10,"No Rider", IF(C2="Bulk","Restaurant Delay", IF(I2>=6,"Distance","None")))))) -> None | R2: =(H2-B2)*1440 -> 48 | S2: =(F2-E2)*1440 -> 3 | T2: =(G2-F2)*1440 -> 3 | U2: =(H2-G2)*1440 -> 31 | V2: =HOUR(B2) -> 12 | W2: =IF(HOUR(B2)>=10,IF(HOUR(B2)<12,"Late Morning",IF(HOUR(B2)<15,"Afternoon",IF(HOUR(B2)<18,"Evening",IF(HOUR(B2)<21,"Peak Night","Late Night")))),"Morning") -> Afternoon | X2: =IF(OR(AND(HOUR(B2)>=12,HOUR(B2)<14),AND(HOUR(B2)>=17,HOUR(B2)<21)),"Peak","Off-Peak") -> Peak | Y2: =I2/U2 -> 0.14419355 | Z2: =L2/I2 -> 21.029083 | AA2: =L2/K2 -> 0.3805668 | AB2: =IF((H2-B2)*1440>45,"Late","On-Time") -> Late | AC2: =IF(P2="Yes",Q2,"No Delay") -> No Delay | AD2: =IF(I2<=2,"Short (0-2km)",IF(I2<=5,"Medium (2-5km)","Long (5+km)")) -> Medium (2-5km)
A3: O2 | B3: 11:36 | C3: Normal | D3: 16 | E3: 11:52 | F3: 11:52 | G3: 0.49861111 | H3: 12:39 | I3: 6.34 | J3: R8 | K3: 218 | L3: 117 | M3: Delivered | N3: 15 | O3: Medium | P3: No | Q3: =IF(M3="Failed", IF(O3="High","Traffic", IF(N3<10,"No Rider","Restaurant Delay")), IF(((H3-B3)*1440 - (D3 + I3*5))<=7,"None", IF(O3="High","Traffic", IF(N3<10,"No Rider", IF(C3="Bulk","Restaurant Delay", IF(I3>=6,"Distance","None")))))) -> Distance | R3: =(H3-B3)*1440 -> 63 | S3: =(F3-E3)*1440 -> 0 | T3: =(G3-F3)*1440 -> 6 | U3: =(H3-G3)*1440 -> 41 | V3: =HOUR(B3) -> 11 | W3: =IF(HOUR(B3)>=10,IF(HOUR(B3)<12,"Late Morning",IF(HOUR(B3)<15,"Afternoon",IF(HOUR(B3)<18,"Evening",IF(HOUR(B3)<21,"Peak Night","Late Night")))),"Morning") -> Late Morning | X3: =IF(OR(AND(HOUR(B3)>=12,HOUR(B3)<14),AND(HOUR(B3)>=17,HOUR(B3)<21)),"Peak","Off-Peak") -> Off-Peak | Y3: =I3/U3 -> 0.15463415 | Z3: =L3/I3 -> 18.454259 | AA3: =L3/K3 -> 0.53669725 | AB3: =IF((H3-B3)*1440>45,"Late","On-Time") -> Late | AC3: =IF(P3="Yes",Q3,"No Delay") -> No Delay | AD3: =IF(I3<=2,"Short (0-2km)",IF(I3<=5,"Medium (2-5km)","Long (5+km)")) -> Long (5+km)
A4: O3 | B4: 11:44 | C4: Normal | D4: 10 | E4: 11:54 | F4: 11:54 | G4: 0.49722222 | H4: 12:33 | I4: 5.55 | J4: R7 | K4: 247 | L4: 105 | M4: Delivered | N4: 12 | O4: Medium | P4: No | Q4: =IF(M4="Failed", IF(O4="High","Traffic", IF(N4<10,"No Rider","Restaurant Delay")), IF(((H4-B4)*1440 - (D4 + I4*5))<=7,"None", IF(O4="High","Traffic", IF(N4<10,"No Rider", IF(C4="Bulk","Restaurant Delay", IF(I4>=6,"Distance","None")))))) -> None | R4: =(H4-B4)*1440 -> 49 | S4: =(F4-E4)*1440 -> 0 | T4: =(G4-F4)*1440 -> 2 | U4: =(H4-G4)*1440 -> 37 | V4: =HOUR(B4) -> 11 | W4: =IF(HOUR(B4)>=10,IF(HOUR(B4)<12,"Late Morning",IF(HOUR(B4)<15,"Afternoon",IF(HOUR(B4)<18,"Evening",IF(HOUR(B4)<21,"Peak Night","Late Night")))),"Morning") -> Late Morning | X4: =IF(OR(AND(HOUR(B4)>=12,HOUR(B4)<14),AND(HOUR(B4)>=17,HOUR(B4)<21)),"Peak","Off-Peak") -> Off-Peak | Y4: =I4/U4 -> 0.15 | Z4: =L4/I4 -> 18.918919 | AA4: =L4/K4 -> 0.42510121 | AB4: =IF((H4-B4)*1440>45,"Late","On-Time") -> Late | AC4: =IF(P4="Yes",Q4,"No Delay") -> No Delay | AD4: =IF(I4<=2,"Short (0-2km)",IF(I4<=5,"Medium (2-5km)","Long (5+km)")) -> Long (5+km)
A5: O4 | B5: 17:12 | C5: Normal | D5: 18 | E5: 17:30 | F5: 17:31 | G5: 0.73055556 | H5: 18:23 | I5: 7.57 | J5: R8 | K5: 323 | L5: 128 | M5: Delivered | N5: 13 | O5: Medium | P5: No | Q5: =IF(M5="Failed", IF(O5="High","Traffic", IF(N5<10,"No Rider","Restaurant Delay")), IF(((H5-B5)*1440 - (D5 + I5*5))<=7,"None", IF(O5="High","Traffic", IF(N5<10,"No Rider", IF(C5="Bulk","Restaurant Delay", IF(I5>=6,"Distance","None")))))) -> Distance | R5: =(H5-B5)*1440 -> 71 | S5: =(F5-E5)*1440 -> 1 | T5: =(G5-F5)*1440 -> 1 | U5: =(H5-G5)*1440 -> 51 | V5: =HOUR(B5) -> 17 | W5: =IF(HOUR(B5)>=10,IF(HOUR(B5)<12,"Late Morning",IF(HOUR(B5)<15,"Afternoon",IF(HOUR(B5)<18,"Evening",IF(HOUR(B5)<21,"Peak Night","Late Night")))),"Morning") -> Evening | X5: =IF(OR(AND(HOUR(B5)>=12,HOUR(B5)<14),AND(HOUR(B5)>=17,HOUR(B5)<21)),"Peak","Off-Peak") -> Peak | Y5: =I5/U5 -> 0.14843137 | Z5: =L5/I5 -> 16.908851 | AA5: =L5/K5 -> 0.39628483 | AB5: =IF((H5-B5)*1440>45,"Late","On-Time") -> Late | AC5: =IF(P5="Yes",Q5,"No Delay") -> No Delay | AD5: =IF(I5<=2,"Short (0-2km)",IF(I5<=5,"Medium (2-5km)","Long (5+km)")) -> Long (5+km)
A6: O5 | B6: 17:50 | C6: Normal | D6: 10 | E6: 18:00 | F6: 18:00 | G6: 0.75069444 | H6: 18:53 | I6: 7.46 | J6: R10 | K6: 335 | L6: 128 | M6: Delivered | N6: 15 | O6: Medium | P6: No | Q6: =IF(M6="Failed", IF(O6="High","Traffic", IF(N6<10,"No Rider","Restaurant Delay")), IF(((H6-B6)*1440 - (D6 + I6*5))<=7,"None", IF(O6="High","Traffic", IF(N6<10,"No Rider", IF(C6="Bulk","Restaurant Delay", IF(I6>=6,"Distance","None")))))) -> Distance | R6: =(H6-B6)*1440 -> 63 | S6: =(F6-E6)*1440 -> 0 | T6: =(G6-F6)*1440 -> 1 | U6: =(H6-G6)*1440 -> 52 | V6: =HOUR(B6) -> 17 | W6: =IF(HOUR(B6)>=10,IF(HOUR(B6)<12,"Late Morning",IF(HOUR(B6)<15,"Afternoon",IF(HOUR(B6)<18,"Evening",IF(HOUR(B6)<21,"Peak Night","Late Night")))),"Morning") -> Evening | X6: =IF(OR(AND(HOUR(B6)>=12,HOUR(B6)<14),AND(HOUR(B6)>=17,HOUR(B6)<21)),"Peak","Off-Peak") -> Peak | Y6: =I6/U6 -> 0.14346154 | Z6: =L6/I6 -> 17.158177 | AA6: =L6/K6 -> 0.38208955 | AB6: =IF((H6-B6)*1440>45,"Late","On-Time") -> Late | AC6: =IF(P6="Yes",Q6,"No Delay") -> No Delay | AD6: =IF(I6<=2,"Short (0-2km)",IF(I6<=5,"Medium (2-5km)","Long (5+km)")) -> Long (5+km)
A7: O6 | B7: 12:03 | C7: Normal | D7: 18 | E7: 12:21 | F7: 12:22 | G7: 0.51805556 | H7: 13:12 | I7: 6.81 | J7: R16 | K7: 300 | L7: 122 | M7: Delivered | N7: 15 | O7: Medium | P7: No | Q7: =IF(M7="Failed", IF(O7="High","Traffic", IF(N7<10,"No Rider","Restaurant Delay")), IF(((H7-B7)*1440 - (D7 + I7*5))<=7,"None", IF(O7="High","Traffic", IF(N7<10,"No Rider", IF(C7="Bulk","Restaurant Delay", IF(I7>=6,"Distance","None")))))) -> Distance | R7: =(H7-B7)*1440 -> 69 | S7: =(F7-E7)*1440 -> 1 | T7: =(G7-F7)*1440 -> 4 | U7: =(H7-G7)*1440 -> 46 | V7: =HOUR(B7) -> 12 | W7: =IF(HOUR(B7)>=10,IF(HOUR(B7)<12,"Late Morning",IF(HOUR(B7)<15,"Afternoon",IF(HOUR(B7)<18,"Evening",IF(HOUR(B7)<21,"Peak Night","Late Night")))),"Morning") -> Afternoon | X7: =IF(OR(AND(HOUR(B7)>=12,HOUR(B7)<14),AND(HOUR(B7)>=17,HOUR(B7)<21)),"Peak","Off-Peak") -> Peak | Y7: =I7/U7 -> 0.14804348 | Z7: =L7/I7 -> 17.914831 | AA7: =L7/K7 -> 0.40666667 | AB7: =IF((H7-B7)*1440>45,"Late","On-Time") -> Late | AC7: =IF(P7="Yes",Q7,"No Delay") -> No Delay | AD7: =IF(I7<=2,"Short (0-2km)",IF(I7<=5,"Medium (2-5km)","Long (5+km)")) -> Long (5+km)
A8: O7 | B8: 18:37 | C8: Normal | D8: 10 | E8: 18:47 | F8: 18:50 | G8: 0.78888889 | H8: 19:34 | I8: 6.21 | J8: R12 | K8: 194 | L8: 113 | M8: Delivered | N8: 15 | O8: Medium | P8: No | Q8: =IF(M8="Failed", IF(O8="High","Traffic", IF(N8<10,"No Rider","Restaurant Delay")), IF(((H8-B8)*1440 - (D8 + I8*5))<=7,"None", IF(O8="High","Traffic", IF(N8<10,"No Rider", IF(C8="Bulk","Restaurant Delay", IF(I8>=6,"Distance","None")))))) -> Distance | R8: =(H8-B8)*1440 -> 57 | S8: =(F8-E8)*1440 -> 3 | T8: =(G8-F8)*1440 -> 6 | U8: =(H8-G8)*1440 -> 38 | V8: =HOUR(B8) -> 18 | W8: =IF(HOUR(B8)>=10,IF(HOUR(B8)<12,"Late Morning",IF(HOUR(B8)<15,"Afternoon",IF(HOUR(B8)<18,"Evening",IF(HOUR(B8)<21,"Peak Night","Late Night")))),"Morning") -> Peak Night | X8: =IF(OR(AND(HOUR(B8)>=12,HOUR(B8)<14),AND(HOUR(B8)>=17,HOUR(B8)<21)),"Peak","Off-Peak") -> Peak | Y8: =I8/U8 -> 0.16342105 | Z8: =L8/I8 -> 18.196457 | AA8: =L8/K8 -> 0.58247423 | AB8: =IF((H8-B8)*1440>45,"Late","On-Time") -> Late | AC8: =IF(P8="Yes",Q8,"No Delay") -> No Delay | AD8: =IF(I8<=2,"Short (0-2km)",IF(I8<=5,"Medium (2-5km)","Long (5+km)")) -> Long (5+km)
A9: O8 | B9: 19:21 | C9: Normal | D9: 20 | E9: 19:41 | F9: 19:41 | G9: 0.82708333 | H9: 20:19 | I9: 4.07 | J9: R13 | K9: 283 | L9: 96 | M9: Delivered | N9: 10 | O9: High | P9: No | Q9: =IF(M9="Failed", IF(O9="High","Traffic", IF(N9<10,"No Rider","Restaurant Delay")), IF(((H9-B9)*1440 - (D9 + I9*5))<=7,"None", IF(O9="High","Traffic", IF(N9<10,"No Rider", IF(C9="Bulk","Restaurant Delay", IF(I9>=6,"Distance","None")))))) -> Traffic | R9: =(H9-B9)*1440 -> 58 | S9: =(F9-E9)*1440 -> 0 | T9: =(G9-F9)*1440 -> 10 | U9: =(H9-G9)*1440 -> 28 | V9: =HOUR(B9) -> 19 | W9: =IF(HOUR(B9)>=10,IF(HOUR(B9)<12,"Late Morning",IF(HOUR(B9)<15,"Afternoon",IF(HOUR(B9)<18,"Evening",IF(HOUR(B9)<21,"Peak Night","Late Night")))),"Morning") -> Peak Night | X9: =IF(OR(AND(HOUR(B9)>=12,HOUR(B9)<14),AND(HOUR(B9)>=17,HOUR(B9)<21)),"Peak","Off-Peak") -> Peak | Y9: =I9/U9 -> 0.14535714 | Z9: =L9/I9 -> 23.587224 | AA9: =L9/K9 -> 0.33922261 | AB9: =IF((H9-B9)*1440>45,"Late","On-Time") -> Late | AC9: =IF(P9="Yes",Q9,"No Delay") -> No Delay | AD9: =IF(I9<=2,"Short (0-2km)",IF(I9<=5,"Medium (2-5km)","Long (5+km)")) -> Medium (2-5km)
A10: O9 | B10: 16:19 | C10: Normal | D10: 10 | E10: 16:29 | F10: 16:32 | G10: 0.69236111 | H10: 16:54 | I10: 3.16 | J10: R17 | K10: 193 | L10: 76 | M10: Delivered | N10: 18 | O10: Low | P10: No | Q10: =IF(M10="Failed", IF(O10="High","Traffic", IF(N10<10,"No Rider","Restaurant Delay")), IF(((H10-B10)*1440 - (D10 + I10*5))<=7,"None", IF(O10="High","Traffic", IF(N10<10,"No Rider", IF(C10="Bulk","Restaurant Delay", IF(I10>=6,"Distance","None")))))) -> None | R10: =(H10-B10)*1440 -> 35 | S10: =(F10-E10)*1440 -> 3 | T10: =(G10-F10)*1440 -> 5 | U10: =(H10-G10)*1440 -> 17 | V10: =HOUR(B10) -> 16 | W10: =IF(HOUR(B10)>=10,IF(HOUR(B10)<12,"Late Morning",IF(HOUR(B10)<15,"Afternoon",IF(HOUR(B10)<18,"Evening",IF(HOUR(B10)<21,"Peak Night","Late Night")))),"Morning") -> Evening | X10: =IF(OR(AND(HOUR(B10)>=12,HOUR(B10)<14),AND(HOUR(B10)>=17,HOUR(B10)<21)),"Peak","Off-Peak") -> Off-Peak | Y10: =I10/U10 -> 0.18588235 | Z10: =L10/I10 -> 24.050633 | AA10: =L10/K10 -> 0.39378238 | AB10: =IF((H10-B10)*1440>45,"Late","On-Time") -> On-Time | AC10: =IF(P10="Yes",Q10,"No Delay") -> No Delay | AD10: =IF(I10<=2,"Short (0-2km)",IF(I10<=5,"Medium (2-5km)","Long (5+km)")) -> Medium (2-5km)
A11: O10 | B11: 13:52 | C11: Normal | D11: 13 | E11: 14:05 | F11: 14:07 | G11: 0.58888889 | H11: 14:36 | I11: 2.63 | J11: R12 | K11: 297 | L11: 80 | M11: Delivered | N11: 16 | O11: Medium | P11: No | Q11: =IF(M11="Failed", IF(O11="High","Traffic", IF(N11<10,"No Rider","Restaurant Delay")), IF(((H11-B11)*1440 - (D11 + I11*5))<=7,"None", IF(O11="High","Traffic", IF(N11<10,"No Rider", IF(C11="Bulk","Restaurant Delay", IF(I11>=6,"Distance","None")))))) -> None | R11: =(H11-B11)*1440 -> 44 | S11: =(F11-E11)*1440 -> 2 | T11: =(G11-F11)*1440 -> 1 | U11: =(H11-G11)*1440 -> 28 | V11: =HOUR(B11) -> 13 | W11: =IF(HOUR(B11)>=10,IF(HOUR(B11)<12,"Late Morning",IF(HOUR(B11)<15,"Afternoon",IF(HOUR(B11)<18,"Evening",IF(HOUR(B11)<21,"Peak Night","Late Night")))),"Morning") -> Afternoon | X11: =IF(OR(AND(HOUR(B11)>=12,HOUR(B11)<14),AND(HOUR(B11)>=17,HOUR(B11)<21)),"Peak","Off-Peak") -> Peak | Y11: =I11/U11 -> 0.093928571 | Z11: =L11/I11 -> 30.418251 | AA11: =L11/K11 -> 0.26936027 | AB11: =IF((H11-B11)*1440>45,"Late","On-Time") -> On-Time | AC11: =IF(P11="Yes",Q11,"No Delay") -> No Delay | AD11: =IF(I11<=2,"Short (0-2km)",IF(I11<=5,"Medium (2-5km)","Long (5+km)")) -> Medium (2-5km)
A12: O11 | B12: 17:50 | C12: Normal | D12: 20 | E12: 18:10 | F12: 18:10 | G12: 0.76111111 | H12: 19:04 | I12: 7.7 | J12: R17 | K12: 369 | L12: 131 | M12: Delivered | N12: 16 | O12: Medium | P12: No | Q12: =IF(M12="Failed", IF(O12="High","Traffic", IF(N12<10,"No Rider","Restaurant Delay")), IF(((H12-B12)*1440 - (D12 + I12*5))<=7,"None", IF(O12="High","Traffic", IF(N12<10,"No Rider", IF(C12="Bulk","Restaurant Delay", IF(I12>=6,"Distance","None")))))) -> Distance | R12: =(H12-B12)*1440 -> 74 | S12: =(F12-E12)*1440 -> 0 | T12: =(G12-F12)*1440 -> 6 | U12: =(H12-G12)*1440 -> 48 | V12: =HOUR(B12) -> 17 | W12: =IF(HOUR(B12)>=10,IF(HOUR(B12)<12,"Late Morning",IF(HOUR(B12)<15,"Afternoon",IF(HOUR(B12)<18,"Evening",IF(HOUR(B12)<21,"Peak Night","Late Night")))),"Morning") -> Evening | X12: =IF(OR(AND(HOUR(B12)>=12,HOUR(B12)<14),AND(HOUR(B12)>=17,HOUR(B12)<21)),"Peak","Off-Peak") -> Peak | Y12: =I12/U12 -> 0.16041667 | Z12: =L12/I12 -> 17.012987 | AA12: =L12/K12 -> 0.35501355 | AB12: =IF((H12-B12)*1440>45,"Late","On-Time") -> Late | AC12: =IF(P12="Yes",Q12,"No Delay") -> No Delay | AD12: =IF(I12<=2,"Short (0-2km)",IF(I12<=5,"Medium (2-5km)","Long (5+km)")) -> Long (5+km)
A13: O12 | B13: 12:12 | C13: Normal | D13: 18 | E13: 12:30 | F13: 12:33 | G13: 0.52361111 | H13: 13:26 | I13: 7.65 | J13: R18 | K13: 295 | L13: 129 | M13: Delivered | N13: 13 | O13: Medium | P13: No | Q13: =IF(M13="Failed", IF(O13="High","Traffic", IF(N13<10,"No Rider","Restaurant Delay")), IF(((H13-B13)*1440 - (D13 + I13*5))<=7,"None", IF(O13="High","Traffic", IF(N13<10,"No Rider", IF(C13="Bulk","Restaurant Delay", IF(I13>=6,"Distance","None")))))) -> Distance | R13: =(H13-B13)*1440 -> 74 | S13: =(F13-E13)*1440 -> 3 | T13: =(G13-F13)*1440 -> 1 | U13: =(H13-G13)*1440 -> 52 | V13: =HOUR(B13) -> 12 | W13: =IF(HOUR(B13)>=10,IF(HOUR(B13)<12,"Late Morning",IF(HOUR(B13)<15,"Afternoon",IF(HOUR(B13)<18,"Evening",IF(HOUR(B13)<21,"Peak Night","Late Night")))),"Morning") -> Afternoon | X13: =IF(OR(AND(HOUR(B13)>=12,HOUR(B13)<14),AND(HOUR(B13)>=17,HOUR(B13)<21)),"Peak","Off-Peak") -> Peak | Y13: =I13/U13 -> 0.14711538 | Z13: =L13/I13 -> 16.862745 | AA13: =L13/K13 -> 0.43728814 | AB13: =IF((H13-B13)*1440>45,"Late","On-Time") -> Late | AC13: =IF(P13="Yes",Q13,"No Delay") -> No Delay | AD13: =IF(I13<=2,"Short (0-2km)",IF(I13<=5,"Medium (2-5km)","Long (5+km)")) -> Long (5+km)
... A251: O250 | B251: 17:44 | C251: Normal | D251: 15 | E251: 17:59 | F251: 18:02 | G251: 0.75347222 | H251: 18:53 | I251: 7.56 | J251: R15 | K251: 333 | L251: 127 | M251: Failed | N251: 16 | O251: Medium | P251: Yes | Q251: =IF(M251="Failed", IF(O251="High","Traffic", IF(N251<10,"No Rider","Restaurant Delay")), IF(((H251-B251)*1440 - (D251 + I251*5))<=7,"None", IF(O251="High","Traffic", IF(N251<10,"No Rider", IF(C251="Bulk","Restaurant Delay", IF(I251>=6,"Distance","None")))))) -> Restaurant Delay | R251: =(H251-B251)*1440 -> 69 | S251: =(F251-E251)*1440 -> 3 | T251: =(G251-F251)*1440 -> 3 | U251: =(H251-G251)*1440 -> 48 | V251: =HOUR(B251) -> 17 | W251: =IF(HOUR(B251)>=10,IF(HOUR(B251)<12,"Late Morning",IF(HOUR(B251)<15,"Afternoon",IF(HOUR(B251)<18,"Evening",IF(HOUR(B251)<21,"Peak Night","Late Night")))),"Morning") -> Evening | X251: =IF(OR(AND(HOUR(B251)>=12,HOUR(B251)<14),AND(HOUR(B251)>=17,HOUR(B251)<21)),"Peak","Off-Peak") -> Peak | Y251: =I251/U251 -> 0.1575 | Z251: =L251/I251 -> 16.798942 | AA251: =L251/K251 -> 0.38138138 | AB251: =IF((H251-B251)*1440>45,"Late","On-Time") -> Late | AC251: =IF(P251="Yes",Q251,"No Delay") -> Restaurant Delay | AD251: =IF(I251<=2,"Short (0-2km)",IF(I251<=5,"Medium (2-5km)","Long (5+km)")) -> Long (5+km)

Sheet KPI_Dashboard
A1: OVERALL OPERATIONS
A3: Total Orders | B3: =COUNTA(Processed_Data!A2:A251) -> 250 | C3: count
A4: Total Delivered | B4: =COUNTIF(Processed_Data!M2:M251,"Delivered") -> 233 | C4: count
A5: Total Failed | B5: =COUNTIF(Processed_Data!M2:M251,"Failed") -> 17 | C5: count
A6: Overall Failure Rate % | B6: =B5/B3 -> 0.068
A7: On-Time Delivery Rate % | B7: =COUNTIF(Processed_Data!AB2:AB251,"On-Time")/B3 -> 0.236
A8: Late Delivery Rate % | B8: =COUNTIF(Processed_Data!AB2:AB251,"Late")/B3 -> 0.764
A10: TIME BREAKDOWN (avg minutes)
A12: Avg Total Delivery Time | B12: =AVERAGE(Processed_Data!R2:R251) -> 56.976 | C12: min
A13: Avg Prep Time | B13: =AVERAGE(Processed_Data!D2:D251) -> 17.92 | C13: min
A14: Avg Prep Wait Gap | B14: =AVERAGE(Processed_Data!S2:S251) -> 2.68 | C14: min
A15: Avg Pickup Lag | B15: =AVERAGE(Processed_Data!T2:T251) -> 4.124 | C15: min
A16: Avg Transit Time | B16: =AVERAGE(Processed_Data!U2:U251) -> 32.252 | C16: min
A18: PEAK vs OFF-PEAK
A20: Peak Avg Delivery Time | B20: =AVERAGEIF(Processed_Data!X2:X251,"Peak",Processed_Data!R2:R251) -> 59.583333 | C20: min
A21: Off-Peak Avg Delivery Time | B21: =AVERAGEIF(Processed_Data!X2:X251,"Off-Peak",Processed_Data!R2:R251) -> 54.059322 | C21: min
A22: Peak vs Off-Peak Difference (min) | B22: =B20-B21 -> 5.5240113 | C22: min
A23: Peak vs Off-Peak Difference % | B23: =B22/B21 -> 0.10218425
A25: NORMAL vs BULK
A27: Normal Order Avg Delivery Time | B27: =AVERAGEIF(Processed_Data!C2:C251,"Normal",Processed_Data!R2:R251) -> 53.563981 | C27: min
A28: Bulk Order Avg Delivery Time | B28: =AVERAGEIF(Processed_Data!C2:C251,"Bulk",Processed_Data!R2:R251) -> 75.435897 | C28: min
A29: Bulk Order Failure Rate % | B29: =COUNTIFS(Processed_Data!C2:C251,"Bulk",Processed_Data!P2:P251,"Yes")/COUNTIF(Processed_Data!C2:C251,"Bulk") -> 0.025641026
A30: Normal Order Failure Rate % | B30: =COUNTIFS(Processed_Data!C2:C251,"Normal",Processed_Data!P2:P251,"Yes")/COUNTIF(Processed_Data!C2:C251,"Normal") -> 0.075829384
A32: TRAFFIC IMPACT
A34: High Traffic Avg Transit Time | B34: =AVERAGEIF(Processed_Data!O2:O251,"High",Processed_Data!U2:U251) -> 31.527778 | C34: min
A35: Medium Traffic Avg Transit Time | B35: =AVERAGEIF(Processed_Data!O2:O251,"Medium",Processed_Data!U2:U251) -> 34.790541 | C35: min
A36: Low Traffic Avg Transit Time | B36: =AVERAGEIF(Processed_Data!O2:O251,"Low",Processed_Data!U2:U251) -> 26.954545 | C36: min
A37: High vs Low Traffic Difference (min) | B37: =B34-B36 -> 4.5732323 | C37: min
A39: FAILURE ANALYSIS
A41: Restaurant Delay Failures | B41: =COUNTIF(Processed_Data!AC2:AC251,"Restaurant Delay") -> 17 | C41: count
A42: % of Failures from Restaurant Delay | B42: =B41/B5 -> 1
A43: Distance Failures | B43: =COUNTIF(Processed_Data!AC2:AC251,"Distance") -> 0 | C43: count
A44: Traffic Failures | B44: =COUNTIF(Processed_Data!AC2:AC251,"Traffic") -> 0 | C44: count
A46: RIDER METRICS
A48: Avg Rider Availability (overall) | B48: =AVERAGE(Processed_Data!N2:N251) -> 14.976 | C48: riders
A49: Peak Hour Avg Rider Availability | B49: =AVERAGEIF(Processed_Data!X2:X251,"Peak",Processed_Data!N2:N251) -> 13.69697 | C49: riders
A50: Off-Peak Avg Rider Availability | B50: =AVERAGEIF(Processed_Data!X2:X251,"Off-Peak",Processed_Data!N2:N251) -> 16.40678 | C50: riders

Sheet Pivot_Tables
A1: TIME PHASE BREAKDOWN | B1: Value (minutes)
A2: Phase
A3: Avg Prep Time | B3: =AVERAGE(Processed_Data!D2:D251) -> 17.92
A4: Avg Prep Wait Gap | B4: =AVERAGE(Processed_Data!S2:S251) -> 2.68
A5: Avg Pickup Lag | B5: =AVERAGE(Processed_Data!T2:T251) -> 4.124
A6: Avg Transit Time | B6: =AVERAGE(Processed_Data!U2:U251) -> 32.252
A7: TOTAL AVG DELIVERY TIME | B7: =SUM(B3:B6) -> 56.976
A10: Time Period | B10: Avg Delivery Time (min) | C10: Order Count | D10: Failures | E10: Failure Rate %
A11: Off-Peak | B11: 54.059322 | C11: 118 | D11: =COUNTIFS(Processed_Data!X2:X251,"Off-Peak",Processed_Data!P2:P251,"Yes") -> 10 | E11: =D11/C11*100 -> 8.4745763
A12: Peak | B12: 59.583333 | C12: 132 | D12: =COUNTIFS(Processed_Data!X2:X251,"Peak",Processed_Data!P2:P251,"Yes") -> 7 | E12: =D12/C12*100 -> 5.3030303
A13: Grand Total | B13: 56.976 | C13: 250 | D13: =SUM(D11:D12) -> 17
A17: Order Type | B17: Avg Prep Time | C17: Avg Total Time | D17: Avg Transit Time | E17: Order Count | F17: Failures | G17: Failure Rate %
A18: Bulk | B18: 32 | C18: 75.435897 | D18: 31.512821 | E18: 39 | F18: =COUNTIFS(Processed_Data!C2:C251,"Bulk",Processed_Data!P2:P251,"Yes") -> 1 | G18: =F18/E18*100 -> 2.5641026
A19: Normal | B19: 15.317536 | C19: 53.563981 | D19: 32.388626 | E19: 211 | F19: =COUNTIFS(Processed_Data!C2:C251,"Normal",Processed_Data!P2:P251,"Yes") -> 16 | G19: =F19/E19*100 -> 7.5829384
A20: Grand Total | B20: 17.92 | C20: 56.976 | D20: 32.252 | E20: 250
A24: Traffic Level | B24: Avg Transit Time | C24: Avg Total Time | D24: Avg Distance km | E24: Order Count
A25: High | B25: 31.527778 | C25: 63.638889 | D25: 3.8711111 | E25: 36
A26: Low | B26: 26.954545 | C26: 51.333333 | D26: 4.3224242 | E26: 66
A27: Medium | B27: 34.790541 | C27: 57.871622 | D27: 4.7938514 | E27: 148
A28: Grand Total | B28: 32.252 | C28: 56.976 | D28: 4.53652 | E28: 250
A32: FAILURE BY TIME SLOT
A33: Time Slot | B33: Total Orders | C33: Failures | D33: Failure Rate %
A34: Late Morning | B34: =COUNTIF(Processed_Data!W2:W251,"Late Morning") -> 52 | C34: =COUNTIFS(Processed_Data!W2:W251,"Late Morning",Processed_Data!P2:P251,"Yes") -> 4 | D34: =C34/B34*100 -> 7.6923077
A35: Afternoon | B35: =COUNTIF(Processed_Data!W2:W251,"Afternoon") -> 62 | C35: =COUNTIFS(Processed_Data!W2:W251,"Afternoon",Processed_Data!P2:P251,"Yes") -> 4 | D35: =C35/B35*100 -> 6.4516129
A36: Evening | B36: =COUNTIF(Processed_Data!W2:W251,"Evening") -> 77 | C36: =COUNTIFS(Processed_Data!W2:W251,"Evening",Processed_Data!P2:P251,"Yes") -> 7 | D36: =C36/B36*100 -> 9.0909091
A37: Peak Night | B37: =COUNTIF(Processed_Data!W2:W251,"Peak Night") -> 59 | C37: =COUNTIFS(Processed_Data!W2:W251,"Peak Night",Processed_Data!P2:P251,"Yes") -> 2 | D37: =C37/B37*100 -> 3.3898305
A38: Grand Total | B38: =SUM(B34:B37) -> 250 | C38: =SUM(C34:C37) -> 17
A42: Rider_ID | B42: Avg Transit | C42: Avg Total Time | D42: Avg Speed | E42: Orders Handled
A43: R14 | B43: 22.6 | C43: 43.4 | D43: 0.12373554 | E43: 5
A44: R2 | B44: 28.928571 | C44: 51.642857 | D44: 0.13047874 | E44: 14
A45: R5 | B45: 29 | C45: 51 | D45: 0.13118808 | E45: 15
A46: R6 | B46: 29.090909 | C46: 49.727273 | D46: 0.1349325 | E46: 11
A47: R17 | B47: 29.666667 | C47: 53.066667 | D47: 0.13278564 | E47: 15
A48: R12 | B48: 30.125 | C48: 53.25 | D48: 0.12698641 | E48: 8
A49: R7 | B49: 30.545455 | C49: 54.090909 | D49: 0.1299318 | E49: 11
A50: R1 | B50: 32.083333 | C50: 57.75 | D50: 0.13107783 | E50: 12
A51: R10 | B51: 32.333333 | C51: 62.2 | D51: 0.13183788 | E51: 15
A52: R4 | B52: 32.4 | C52: 63.7 | D52: 0.1359726 | E52: 10
A53: R19 | B53: 32.736842 | C53: 53.052632 | D53: 0.14222022 | E53: 19
A54: R15 | B54: 33.214286 | C54: 56.214286 | D54: 0.14040626 | E54: 14
...

Sheet Charts
H1: Phase | I1: Minutes
H2: Avg Prep Time | I2: 17.92
H3: Avg Prep Wait Gap | I3: 2.68
H4: Avg Pickup Lag | I4: 4.124
H5: Avg Transit Time | I5: 32.252
H9: Time Period | I9: Avg Delivery Time (min)
H10: Off-Peak | I10: 54.059322
H11: Peak | I11: 59.583333
H14: Order Type | I14: Avg Prep Time | J14: Avg Total Time
H15: Bulk | I15: 32 | J15: 75.435897
H16: Normal | I16: 15.317536 | J16: 53.563981
H19: Traffic Level | I19: Avg Transit Time | J19: Avg Distance km
H20: High | I20: 31.527778 | J20: 3.8711111
H21: Low | I21: 26.954545 | J21: 4.3224242
H22: Medium | I22: 34.790541 | J22: 4.7938514
H25: Time Slot | I25: Failure Rate %
H26: Late Morning | I26: 7.6923077
H27: Afternoon | I27: 6.4516129
H28: Evening | I28: 9.0909091
H29: Peak Night | I29: 3.3898305
H32: Rider_ID | I32: Avg Transit
H33: R14 | I33: 22.6
H34: R2 | I34: 28.928571
H35: R5 | I35: 29
H36: R6 | I36: 29.090909
H37: R17 | I37: 29.666667
H38: R12 | I38: 30.125
H39: R7 | I39: 30.545455
H40: R1 | I40: 32.083333
H41: R10 | I41: 32.333333
H42: R4 | I42: 32.4
H43: R19 | I43: 32.736842
H44: R15 | I44: 33.214286
... H52: R11 | I52: 38.181818
H55: Hour | I55: Order Count | J55: Avg Rider Availability
H56: 10 | I56: 30 | J56: 15.2
H57: 11 | I57: 22 | J57: 14.909091
H58: 12 | I58: 21 | J58: 15
H59: 13 | I59: 19 | J59: 15.210526
H60: 14 | I60: 22 | J60: 17.136364
...
